Loaded module: python3/3.8.2
WARNING:absl:No GPU/TPU found, falling back to CPU. (Set TF_CPP_MIN_LOG_LEVEL=0 and rerun for more info.)
Traceback (most recent call last):
  File "/zhome/77/8/118225/.local/lib/python3.8/site-packages/scipy/io/matlab/mio.py", line 39, in _open_file
    return open(file_like, mode), True
FileNotFoundError: [Errno 2] No such file or directory: 'Data/dataM-corpora-callosa-ipmi-full.mat'

During handling of the above exception, another exception occurred:

Traceback (most recent call last):
  File "corpus_callosum.py", line 120, in <module>
    data=io.loadmat('Data/dataM-corpora-callosa-ipmi-full.mat')
  File "/zhome/77/8/118225/.local/lib/python3.8/site-packages/scipy/io/matlab/mio.py", line 222, in loadmat
    with _open_file_context(file_name, appendmat) as f:
  File "/appl/python/3.8.2/lib/python3.8/contextlib.py", line 113, in __enter__
    return next(self.gen)
  File "/zhome/77/8/118225/.local/lib/python3.8/site-packages/scipy/io/matlab/mio.py", line 17, in _open_file_context
    f, opened = _open_file(file_like, appendmat, mode)
  File "/zhome/77/8/118225/.local/lib/python3.8/site-packages/scipy/io/matlab/mio.py", line 45, in _open_file
    return open(file_like, mode), True
FileNotFoundError: [Errno 2] No such file or directory: 'Data/dataM-corpora-callosa-ipmi-full.mat'
